package TestPackage;

public class finallyconcept {

	public static void main(String[] args) {
		test();
		test2();
		division();
	
	}

	public static void test() {
		try {
			System.out.println("try block");
		}
		catch(Exception e) {
			System.out.println("catch block");
			}
		finally {
			System.out.println("finally block");
		}
		
	} 
	
	public static void test2() {
		try {
			System.out.println("try block");
			}
		finally {
			System.out.println("Finally block");
		}
		
	}
	
	public static void division() {
		int i=10;
		try {
			System.out.println("Inside try block");
			int k=i/0;
		}
		catch(ArithmeticException e)
		{
			System.out.println("Inside catch block");
			System.out.println("divide by zero error");
		}
		finally {
			System.out.println("execute this code even after exception");
		}
		
		
	}
}
